Tue, 08, Nov, 2016 19:59:26 [WARNING]:base.py, django.request, in line 170 >> 
Not Found: /http:/127.0.0.1:8000/api/0.1.4/user/
Tue, 08, Nov, 2016 19:59:39 [WARNING]:base.py, django.request, in line 170 >> 
Not Found: /http:/127.0.0.1:8000/api/0.1.4/user/
Tue, 08, Nov, 2016 19:59:51 [WARNING]:base.py, django.request, in line 170 >> 
Not Found: /favicon.ico
Tue, 08, Nov, 2016 20:02:08 [WARNING]:base.py, django.request, in line 170 >> 
Not Found: /http:/127.0.0.1:8000/api/0.1.4/user/
Tue, 08, Nov, 2016 20:02:46 [WARNING]:base.py, django.request, in line 170 >> 
Not Found: /http:/127.0.0.1:8000/api/0.1.4/user/
Tue, 08, Nov, 2016 20:14:36 [WARNING]:base.py, django.request, in line 170 >> 
Not Found: /http:/127.0.0.1:8000/api/0.1.4/user/
Tue, 08, Nov, 2016 20:14:54 [WARNING]:base.py, django.request, in line 170 >> 
Not Found: /http:/127.0.0.1:8000/api/0.1.4/user/
Tue, 08, Nov, 2016 20:17:27 [WARNING]:base.py, django.request, in line 170 >> 
Not Found: /http:/127.0.0.1:8000/api/0.1.4/user/
Tue, 08, Nov, 2016 20:18:03 [WARNING]:base.py, django.request, in line 170 >> 
Not Found: /http:/127.0.0.1:8000/api/0.1.4/user/
Tue, 08, Nov, 2016 20:18:18 [WARNING]:base.py, django.request, in line 170 >> 
Not Found: /http:/127.0.0.1:8000/api/0.1.4/user/
Tue, 08, Nov, 2016 20:18:26 [WARNING]:base.py, django.request, in line 170 >> 
Not Found: /http:/127.0.0.1:8000/api/0.1.4/user/
Tue, 08, Nov, 2016 20:19:31 [WARNING]:base.py, django.request, in line 170 >> 
Not Found: /http:/127.0.0.1:8000/api/0.1.4/user/
Tue, 08, Nov, 2016 20:19:35 [WARNING]:base.py, django.request, in line 170 >> 
Not Found: /http:/127.0.0.1:8000/api/0.1.4/user/
Tue, 08, Nov, 2016 21:12:35 [WARNING]:base.py, django.request, in line 170 >> 
Not Found: /http:/127.0.0.1:8000/api/0.1.4/user/
Tue, 08, Nov, 2016 21:36:21 [WARNING]:base.py, django.request, in line 170 >> 
Not Found: /http:/127.0.0.1:8000/api/0.1.4/user/
Tue, 08, Nov, 2016 21:37:07 [WARNING]:base.py, django.request, in line 170 >> 
Not Found: /http:/127.0.0.1:8000/api/0.1.4/user/
Tue, 08, Nov, 2016 21:41:51 [WARNING]:base.py, django.request, in line 170 >> 
Not Found: /http:/127.0.0.1:8000/api/0.1.4/user/
Tue, 08, Nov, 2016 21:48:30 [WARNING]:base.py, django.request, in line 170 >> 
Not Found: /http:/127.0.0.1:8000/api/0.1.4/user/
Tue, 08, Nov, 2016 21:48:58 [WARNING]:base.py, django.request, in line 170 >> 
Not Found: /http:/127.0.0.1:8000/api/0.1.4/user/
Tue, 08, Nov, 2016 21:51:11 [WARNING]:base.py, django.request, in line 170 >> 
Not Found: /http:/127.0.0.1:8000/api/0.1.4/user/
Tue, 08, Nov, 2016 21:54:25 [WARNING]:base.py, django.request, in line 170 >> 
Not Found: /http:/127.0.0.1:8000/api/0.1.4/user/
Tue, 08, Nov, 2016 22:00:16 [WARNING]:base.py, django.request, in line 170 >> 
Not Found: /http:/127.0.0.1:8000/api/0.1.4/user/
Tue, 08, Nov, 2016 22:14:17 [ERROR]:base.py, django.request, in line 256 >> 
Internal Server Error: /api/0.1.4/user/
Traceback (most recent call last):
  File "/Library/Python/2.7/site-packages/django/core/handlers/base.py", line 132, in get_response
    response = wrapped_callback(request, *callback_args, **callback_kwargs)
  File "/Library/Python/2.7/site-packages/django/views/decorators/csrf.py", line 58, in wrapped_view
    return view_func(*args, **kwargs)
  File "/Library/Python/2.7/site-packages/rest_framework/viewsets.py", line 87, in view
    return self.dispatch(request, *args, **kwargs)
  File "/Users/wangyi/PycharmProjects/hack_Fudan/info_tracker/api/views.py", line 117, in dispatch
    response = self.handle_exception(exc)
  File "/Users/wangyi/PycharmProjects/hack_Fudan/info_tracker/api/views.py", line 100, in dispatch
    self.initial(request, *args, **kwargs)
  File "/Library/Python/2.7/site-packages/rest_framework/views.py", line 376, in initial
    self.perform_authentication(request)
  File "/Library/Python/2.7/site-packages/rest_framework/views.py", line 310, in perform_authentication
    request.user
  File "/Library/Python/2.7/site-packages/rest_framework/request.py", line 353, in __getattribute__
    return super(Request, self).__getattribute__(attr)
  File "/Library/Python/2.7/site-packages/rest_framework/request.py", line 193, in user
    self._authenticate()
  File "/Library/Python/2.7/site-packages/rest_framework/request.py", line 316, in _authenticate
    user_auth_tuple = authenticator.authenticate(self)
  File "/Users/wangyi/PycharmProjects/hack_Fudan/info_tracker/api/auth/authentication.py", line 140, in authenticate
    signature_string = self.compose_signature(req, signed_headers)
  File "/Users/wangyi/PycharmProjects/hack_Fudan/info_tracker/api/auth/authentication.py", line 210, in compose_signature
    ret = encode_signed_headers(signed_headers)
  File "/Users/wangyi/PycharmProjects/hack_Fudan/info_tracker/api/auth/authentication.py", line 207, in encode_signed_headers
    map_ob = map(args_processor, signed_headers.items())
  File "/Users/wangyi/PycharmProjects/hack_Fudan/info_tracker/api/auth/authentication.py", line 206, in <lambda>
    ': '.join((key.lower(), val[0] if isinstance(val, (list, tuple)) else val))
TypeError: sequence item 1: expected string, NoneType found
Tue, 08, Nov, 2016 22:14:34 [ERROR]:base.py, django.request, in line 256 >> 
Internal Server Error: /api/0.1.4/user/
Traceback (most recent call last):
  File "/Library/Python/2.7/site-packages/django/core/handlers/base.py", line 132, in get_response
    response = wrapped_callback(request, *callback_args, **callback_kwargs)
  File "/Library/Python/2.7/site-packages/django/views/decorators/csrf.py", line 58, in wrapped_view
    return view_func(*args, **kwargs)
  File "/Library/Python/2.7/site-packages/rest_framework/viewsets.py", line 87, in view
    return self.dispatch(request, *args, **kwargs)
  File "/Users/wangyi/PycharmProjects/hack_Fudan/info_tracker/api/views.py", line 117, in dispatch
    response = self.handle_exception(exc)
  File "/Users/wangyi/PycharmProjects/hack_Fudan/info_tracker/api/views.py", line 100, in dispatch
    self.initial(request, *args, **kwargs)
  File "/Library/Python/2.7/site-packages/rest_framework/views.py", line 376, in initial
    self.perform_authentication(request)
  File "/Library/Python/2.7/site-packages/rest_framework/views.py", line 310, in perform_authentication
    request.user
  File "/Library/Python/2.7/site-packages/rest_framework/request.py", line 353, in __getattribute__
    return super(Request, self).__getattribute__(attr)
  File "/Library/Python/2.7/site-packages/rest_framework/request.py", line 193, in user
    self._authenticate()
  File "/Library/Python/2.7/site-packages/rest_framework/request.py", line 316, in _authenticate
    user_auth_tuple = authenticator.authenticate(self)
  File "/Users/wangyi/PycharmProjects/hack_Fudan/info_tracker/api/auth/authentication.py", line 140, in authenticate
    signature_string = self.compose_signature(req, signed_headers)
  File "/Users/wangyi/PycharmProjects/hack_Fudan/info_tracker/api/auth/authentication.py", line 210, in compose_signature
    ret = encode_signed_headers(signed_headers)
  File "/Users/wangyi/PycharmProjects/hack_Fudan/info_tracker/api/auth/authentication.py", line 207, in encode_signed_headers
    map_ob = map(args_processor, signed_headers.items())
  File "/Users/wangyi/PycharmProjects/hack_Fudan/info_tracker/api/auth/authentication.py", line 206, in <lambda>
    ': '.join((key.lower(), val[0] if isinstance(val, (list, tuple)) else val))
TypeError: sequence item 1: expected string, NoneType found
Tue, 08, Nov, 2016 22:17:02 [ERROR]:base.py, django.request, in line 256 >> 
Internal Server Error: /api/0.1.4/user/
Traceback (most recent call last):
  File "/Library/Python/2.7/site-packages/django/core/handlers/base.py", line 132, in get_response
    response = wrapped_callback(request, *callback_args, **callback_kwargs)
  File "/Library/Python/2.7/site-packages/django/views/decorators/csrf.py", line 58, in wrapped_view
    return view_func(*args, **kwargs)
  File "/Library/Python/2.7/site-packages/rest_framework/viewsets.py", line 87, in view
    return self.dispatch(request, *args, **kwargs)
  File "/Users/wangyi/PycharmProjects/hack_Fudan/info_tracker/api/views.py", line 117, in dispatch
    response = self.handle_exception(exc)
  File "/Users/wangyi/PycharmProjects/hack_Fudan/info_tracker/api/views.py", line 100, in dispatch
    self.initial(request, *args, **kwargs)
  File "/Library/Python/2.7/site-packages/rest_framework/views.py", line 376, in initial
    self.perform_authentication(request)
  File "/Library/Python/2.7/site-packages/rest_framework/views.py", line 310, in perform_authentication
    request.user
  File "/Library/Python/2.7/site-packages/rest_framework/request.py", line 353, in __getattribute__
    return super(Request, self).__getattribute__(attr)
  File "/Library/Python/2.7/site-packages/rest_framework/request.py", line 193, in user
    self._authenticate()
  File "/Library/Python/2.7/site-packages/rest_framework/request.py", line 316, in _authenticate
    user_auth_tuple = authenticator.authenticate(self)
  File "/Users/wangyi/PycharmProjects/hack_Fudan/info_tracker/api/auth/authentication.py", line 140, in authenticate
    signature_string = self.compose_signature(req, signed_headers)
  File "/Users/wangyi/PycharmProjects/hack_Fudan/info_tracker/api/auth/authentication.py", line 210, in compose_signature
    ret = encode_signed_headers(signed_headers)
  File "/Users/wangyi/PycharmProjects/hack_Fudan/info_tracker/api/auth/authentication.py", line 207, in encode_signed_headers
    map_ob = map(args_processor, signed_headers.items())
  File "/Users/wangyi/PycharmProjects/hack_Fudan/info_tracker/api/auth/authentication.py", line 206, in <lambda>
    ': '.join((key.lower(), val[0] if isinstance(val, (list, tuple)) else val))
TypeError: sequence item 1: expected string, NoneType found
Tue, 08, Nov, 2016 22:21:07 [ERROR]:base.py, django.request, in line 256 >> 
Internal Server Error: /api/0.1.4/user/
Traceback (most recent call last):
  File "/Library/Python/2.7/site-packages/django/core/handlers/base.py", line 132, in get_response
    response = wrapped_callback(request, *callback_args, **callback_kwargs)
  File "/Library/Python/2.7/site-packages/django/views/decorators/csrf.py", line 58, in wrapped_view
    return view_func(*args, **kwargs)
  File "/Library/Python/2.7/site-packages/rest_framework/viewsets.py", line 87, in view
    return self.dispatch(request, *args, **kwargs)
  File "/Users/wangyi/PycharmProjects/hack_Fudan/info_tracker/api/views.py", line 117, in dispatch
    response = self.handle_exception(exc)
  File "/Users/wangyi/PycharmProjects/hack_Fudan/info_tracker/api/views.py", line 100, in dispatch
    self.initial(request, *args, **kwargs)
  File "/Library/Python/2.7/site-packages/rest_framework/views.py", line 376, in initial
    self.perform_authentication(request)
  File "/Library/Python/2.7/site-packages/rest_framework/views.py", line 310, in perform_authentication
    request.user
  File "/Library/Python/2.7/site-packages/rest_framework/request.py", line 353, in __getattribute__
    return super(Request, self).__getattribute__(attr)
  File "/Library/Python/2.7/site-packages/rest_framework/request.py", line 193, in user
    self._authenticate()
  File "/Library/Python/2.7/site-packages/rest_framework/request.py", line 316, in _authenticate
    user_auth_tuple = authenticator.authenticate(self)
  File "/Users/wangyi/PycharmProjects/hack_Fudan/info_tracker/api/auth/authentication.py", line 140, in authenticate
    signature_string = self.compose_signature(req, signed_headers)
  File "/Users/wangyi/PycharmProjects/hack_Fudan/info_tracker/api/auth/authentication.py", line 210, in compose_signature
    ret = encode_signed_headers(signed_headers)
  File "/Users/wangyi/PycharmProjects/hack_Fudan/info_tracker/api/auth/authentication.py", line 207, in encode_signed_headers
    map_ob = map(args_processor, signed_headers.items())
  File "/Users/wangyi/PycharmProjects/hack_Fudan/info_tracker/api/auth/authentication.py", line 206, in <lambda>
    ': '.join((key.lower(), val[0] if isinstance(val, (list, tuple)) else val))
TypeError: sequence item 1: expected string, NoneType found
